<?xml version="1.0" ?>
<!-- =================================================================================== -->
<!-- |    This document was autogenerated by xacro from /home/arash/ros2_ws/install/husky_description/share/husky_description/urdf/husky.urdf.xacro | -->
<!-- |    EDITING THIS FILE BY HAND IS NOT RECOMMENDED                                 | -->
<!-- =================================================================================== -->
<!--
Software License Agreement (BSD)

\file      husky.urdf.xacro
\authors   Paul Bovbel <pbovbel@clearpathrobotics.com>, Devon Ash <dash@clearpathrobotics.com>
\copyright Copyright (c) 2015, Clearpath Robotics, Inc., All rights reserved.

Redistribution and use in source and binary forms, with or without modification, are permitted provided that
the following conditions are met:
 * Redistributions of source code must retain the above copyright notice, this list of conditions and the
   following disclaimer.
 * Redistributions in binary form must reproduce the above copyright notice, this list of conditions and the
   following disclaimer in the documentation and/or other materials provided with the distribution.
 * Neither the name of Clearpath Robotics nor the names of its contributors may be used to endorse or promote
   products derived from this software without specific prior written permission.

THIS SOFTWARE IS PROVIDED BY THE COPYRIGHT HOLDERS AND CONTRIBUTORS "AS IS" AND ANY EXPRESS OR IMPLIED WAR-
RANTIES, INCLUDING, BUT NOT LIMITED TO, THE IMPLIED WARRANTIES OF MERCHANTABILITY AND FITNESS FOR A PARTICULAR
PURPOSE ARE DISCLAIMED. IN NO EVENT SHALL THE COPYRIGHT HOLDER OR CONTRIBUTORS BE LIABLE FOR ANY DIRECT, IN-
DIRECT, INCIDENTAL, SPECIAL, EXEMPLARY, OR CONSEQUENTIAL DAMAGES (INCLUDING, BUT NOT LIMITED TO, PROCUREMENT
OF SUBSTITUTE GOODS OR SERVICES; LOSS OF USE, DATA, OR PROFITS; OR BUSINESS INTERRUPTION) HOWEVER CAUSED AND
ON ANY THEORY OF LIABILITY, WHETHER IN CONTRACT, STRICT LIABILITY, OR TORT (INCLUDING NEGLIGENCE OR OTHERWISE)
ARISING IN ANY WAY OUT OF THE USE OF THIS SOFTWARE, EVEN IF ADVISED OF THE POSSIBILITY OF SUCH DAMAGE.
-->
<robot name="husky">
  <material name="dark_grey">
    <color rgba="0.2 0.2 0.2 1.0"/>
  </material>
  <material name="medium_grey">
    <color rgba="0.6 0.6 0.6 1.0"/>
  </material>
  <material name="light_grey">
    <color rgba="0.8 0.8 0.8 1.0"/>
  </material>
  <material name="yellow">
    <color rgba="0.8 0.8 0.0 1.0"/>
  </material>
  <material name="black">
    <color rgba="0.15 0.15 0.15 1.0"/>
  </material>
  <material name="white">
    <color rgba="1.0 1.0 1.0 1.0"/>
  </material>
  <material name="red">
    <color rgba="1.0 0.0 0.0 1.0"/>
  </material>
  <!-- Base link is the center of the robot's bottom plate -->
  <link name="base_link">
    <visual>
      <origin rpy="0 0 0" xyz="0 0 0"/>
      <geometry>
        <mesh filename="/home/arash/ros2_ws/src/husky_description/meshes/base_link.dae"/>
      </geometry>
    </visual>
 

    <collision>
      <origin rpy="0 0 0" xyz="0.0 0 0.061875"/>
      <geometry>
        <box size="0.9874 0.5709 0.12375"/>
      </geometry>
    </collision>
    <collision>
      <origin rpy="0 0 0" xyz="0 0 0.17562499999999998"/>
      <geometry>
        <box size="0.7899200000000001 0.5709 0.10375"/>
      </geometry>
    </collision>
   
  </link>
  <!-- Base footprint is on the ground under the robot -->
  <link name="base_footprint"/>
  <joint name="base_footprint_joint" type="fixed">
    <origin rpy="0 0 0" xyz="0 0 -0.13228"/>
    <parent link="base_link"/>
    <child link="base_footprint"/>
  </joint>
  <!-- Inertial link stores the robot's inertial information -->
  <link name="inertial_link">
    <inertial>
      <mass value="46.034"/>
      <origin xyz="-0.00065 -0.085 0.062"/>
      <inertia ixx="0.6022" ixy="-0.02364" ixz="-0.1197" iyy="1.7386" iyz="-0.001544" izz="2.0296"/>
    </inertial>
  </link>
  <joint name="inertial_joint" type="fixed">
    <origin rpy="0 0 0" xyz="0 0 0"/>
    <parent link="base_link"/>
    <child link="inertial_link"/>
  </joint>
  <link name="front_left_wheel_link">
    <inertial>
      <mass value="2.637"/>
      <origin xyz="0 0 0"/>
      <inertia ixx="0.02467" ixy="0" ixz="0" iyy="0.04411" iyz="0" izz="0.02467"/>
    </inertial>
    <visual>
      <origin rpy="0 0 0" xyz="0 0 0"/>
      <geometry>
        <mesh filename="/home/arash/ros2_ws/src/husky_description/meshes/wheel.dae"/>
      </geometry>
    </visual>
    <collision>
      <origin rpy="1.570795 0 0" xyz="0 0 0"/>
      <geometry>
        <cylinder length="0.1143" radius="0.1651"/>
      </geometry>
    </collision>
  </link>
  <gazebo reference="front_left_wheel_link">
    <mu1 value="1.0"/>
    <mu2 value="1.0"/>
    <kp value="10000000.0"/>
    <kd value="1.0"/>
    <fdir1 value="1 0 0"/>
  </gazebo>
  <joint name="front_left_wheel" type="continuous">
    <parent link="base_link"/>
    <child link="front_left_wheel_link"/>
    <origin rpy="0 0 0" xyz="0.256 0.2854 0.03282"/>
    <axis rpy="0 0 0" xyz="0 1 0"/>
  </joint>
  <transmission name="front_left_wheel_trans" type="SimpleTransmission">
    <type>transmission_interface/SimpleTransmission</type>
    <actuator name="front_left_wheel_motor">
      <mechanicalReduction>1</mechanicalReduction>
    </actuator>
    <joint name="front_left_wheel">
      <hardwareInterface>hardware_interface/VelocityJointInterface</hardwareInterface>
    </joint>
  </transmission>
  <link name="front_right_wheel_link">
    <inertial>
      <mass value="2.637"/>
      <origin xyz="0 0 0"/>
      <inertia ixx="0.02467" ixy="0" ixz="0" iyy="0.04411" iyz="0" izz="0.02467"/>
    </inertial>
    <visual>
      <origin rpy="0 0 0" xyz="0 0 0"/>
      <geometry>
        <mesh filename="/home/arash/ros2_ws/src/husky_description/meshes/wheel.dae"/>
      </geometry>
    </visual>
    <collision>
      <origin rpy="1.570795 0 0" xyz="0 0 0"/>
      <geometry>
        <cylinder length="0.1143" radius="0.1651"/>
      </geometry>
    </collision>
  </link>
  <gazebo reference="front_right_wheel_link">
    <mu1 value="1.0"/>
    <mu2 value="1.0"/>
    <kp value="10000000.0"/>
    <kd value="1.0"/>
    <fdir1 value="1 0 0"/>
  </gazebo>
  <joint name="front_right_wheel" type="continuous">
    <parent link="base_link"/>
    <child link="front_right_wheel_link"/>
    <origin rpy="0 0 0" xyz="0.256 -0.2854 0.03282"/>
    <axis rpy="0 0 0" xyz="0 1 0"/>
  </joint>
  <transmission name="front_right_wheel_trans" type="SimpleTransmission">
    <type>transmission_interface/SimpleTransmission</type>
    <actuator name="front_right_wheel_motor">
      <mechanicalReduction>1</mechanicalReduction>
    </actuator>
    <joint name="front_right_wheel">
      <hardwareInterface>hardware_interface/VelocityJointInterface</hardwareInterface>
    </joint>
  </transmission>
  <link name="rear_left_wheel_link">
    <inertial>
      <mass value="2.637"/>
      <origin xyz="0 0 0"/>
      <inertia ixx="0.02467" ixy="0" ixz="0" iyy="0.04411" iyz="0" izz="0.02467"/>
    </inertial>
    <visual>
      <origin rpy="0 0 0" xyz="0 0 0"/>
      <geometry>
        <mesh filename="/home/arash/ros2_ws/src/husky_description/meshes/wheel.dae"/>
      </geometry>
    </visual>
    <collision>
      <origin rpy="1.570795 0 0" xyz="0 0 0"/>
      <geometry>
        <cylinder length="0.1143" radius="0.1651"/>
      </geometry>
    </collision>
  </link>
  <gazebo reference="rear_left_wheel_link">
    <mu1 value="1.0"/>
    <mu2 value="1.0"/>
    <kp value="10000000.0"/>
    <kd value="1.0"/>
    <fdir1 value="1 0 0"/>
  </gazebo>
  <joint name="rear_left_wheel" type="continuous">
    <parent link="base_link"/>
    <child link="rear_left_wheel_link"/>
    <origin rpy="0 0 0" xyz="-0.256 0.2854 0.03282"/>
    <axis rpy="0 0 0" xyz="0 1 0"/>
  </joint>
  <transmission name="rear_left_wheel_trans" type="SimpleTransmission">
    <type>transmission_interface/SimpleTransmission</type>
    <actuator name="rear_left_wheel_motor">
      <mechanicalReduction>1</mechanicalReduction>
    </actuator>
    <joint name="rear_left_wheel">
      <hardwareInterface>hardware_interface/VelocityJointInterface</hardwareInterface>
    </joint>
  </transmission>
  <link name="rear_right_wheel_link">
    <inertial>
      <mass value="2.637"/>
      <origin xyz="0 0 0"/>
      <inertia ixx="0.02467" ixy="0" ixz="0" iyy="0.04411" iyz="0" izz="0.02467"/>
    </inertial>
    <visual>
      <origin rpy="0 0 0" xyz="0 0 0"/>
      <geometry>
        <mesh filename="/home/arash/ros2_ws/src/husky_description/meshes/wheel.dae"/>
      </geometry>
    </visual>
    <collision>
      <origin rpy="1.570795 0 0" xyz="0 0 0"/>
      <geometry>
        <cylinder length="0.1143" radius="0.1651"/>
      </geometry>
    </collision>
  </link>
  <gazebo reference="rear_right_wheel_link">
    <mu1 value="1.0"/>
    <mu2 value="1.0"/>
    <kp value="10000000.0"/>
    <kd value="1.0"/>
    <fdir1 value="1 0 0"/>
  </gazebo>
  <joint name="rear_right_wheel" type="continuous">
    <parent link="base_link"/>
    <child link="rear_right_wheel_link"/>
    <origin rpy="0 0 0" xyz="-0.256 -0.2854 0.03282"/>
    <axis rpy="0 0 0" xyz="0 1 0"/>
  </joint>
  <transmission name="rear_right_wheel_trans" type="SimpleTransmission">
    <type>transmission_interface/SimpleTransmission</type>
    <actuator name="rear_right_wheel_motor">
      <mechanicalReduction>1</mechanicalReduction>
    </actuator>
    <joint name="rear_right_wheel">
      <hardwareInterface>hardware_interface/VelocityJointInterface</hardwareInterface>
    </joint>
  </transmission>
  <!--
      CHASSIS: Spawn and attach default chassis.
               Currently, no customization available.
    -->
  <!-- Spawn Husky chassis -->
  <link name="top_chassis_link">
    <visual>
      <origin rpy="0 0 0" xyz="0 0 0"/>
      <geometry>
        <mesh filename="/home/arash/ros2_ws/src/husky_description/meshes/top_chassis.dae"/>
      </geometry>
    </visual>
  </link>
  <!-- Attach chassis to the robot -->
  <joint name="top_chassis_joint" type="fixed">
    <parent link="base_link"/>
    <child link="top_chassis_link"/>
  </joint>
  <link name="front_bumper_link">
    <visual>
      <geometry>
        <mesh filename="/home/arash/ros2_ws/src/husky_description/meshes/bumper.dae"/>
      </geometry>
    </visual>
  </link>
  <!-- Attach front bumper -->
  <joint name="front_bumper" type="fixed">
    <origin rpy="0 0 0" xyz="0.48 0 0.091"/>
    <parent link="base_link"/>
    <child link="front_bumper_link"/>
  </joint>
  <link name="rear_bumper_link">
    <visual>
      <geometry>
        <mesh filename="/home/arash/ros2_ws/src/husky_description/meshes/bumper.dae"/>
      </geometry>
    </visual>
  </link>
  <!-- Attach rear bumper -->
  <joint name="rear_bumper" type="fixed">
    <origin rpy="0 0 3.14159" xyz="-0.48 0 0.091"/>
    <parent link="base_link"/>
    <child link="rear_bumper_link"/>
  </joint>
  <!-- Spawn user rails -->
  <link name="user_rail_link">
    <visual>
      <geometry>
        <mesh filename="/home/arash/ros2_ws/src/husky_description/meshes/user_rail.dae"/>
      </geometry>
    </visual>
  </link>
  <!-- Attach user rails to base link -->
  <joint name="user_rail" type="fixed">
    <origin rpy="0 0 0" xyz="0.272 0 0.245"/>
    <parent link="base_link"/>
    <child link="user_rail_link"/>
  </joint>
  <!-- Spawn default top plate -->
  <link name="top_plate_link">
    <visual>
      <origin rpy="0 0 0" xyz="0 0 0"/>
      <geometry>
        <mesh filename="/home/arash/ros2_ws/src/husky_description/meshes/top_plate.dae"/>
      </geometry>
    </visual>
    <collision>
      <origin rpy="0 0 0" xyz="0 0 0"/>
      <geometry>
        <mesh filename="/home/arash/ros2_ws/src/husky_description/meshes/top_plate.stl"/>
      </geometry>
    </collision>
  </link>
  <!-- Attach default top plate -->
  <joint name="top_plate_joint" type="fixed">
    <parent link="base_link"/>
    <child link="top_plate_link"/>
    <origin rpy="0 0 0" xyz="0.0812 0 0.245"/>
  </joint>
  <!-- Default top plate front link -->
  <link name="top_plate_front_link"/>
  <joint name="top_plate_front_joint" type="fixed">
    <parent link="top_plate_link"/>
    <child link="top_plate_front_link"/>
    <origin rpy="0 0 0" xyz="0.36367 0 0.00639"/>
  </joint>
  <!-- Default top plate rear link-->
  <link name="top_plate_rear_link"/>
  <joint name="top_plate_rear_joint" type="fixed">
    <parent link="top_plate_link"/>
    <child link="top_plate_rear_link"/>
    <origin rpy="0 0 0" xyz="-0.36633 0 0.00639"/>
  </joint>
  <link name="sensor_arch_base_link"/>
  <!-- Spawn the sensor arch link -->
  <link name="sensor_arch_mount_link">
    <origin rpy="0 0 0" xyz="0 0 0"/>
    <visual>
      <geometry>
        <mesh filename="/home/arash/ros2_ws/src/husky_description/meshes/accessories/510_mm_sensor_arch.dae"/>
      </geometry>
    </visual>
    <collision>
      <origin rpy="0 0 0" xyz="0 0 0"/>
      <geometry>
        <mesh filename="/home/arash/ros2_ws/src/husky_description/meshes/accessories/510_mm_sensor_arch.dae"/>
      </geometry>
    </collision>
  </link>
  <joint name="sensor_arch_base_link_joint" type="fixed">
    <parent link="top_plate_link"/>
    <child link="sensor_arch_base_link"/>
    <origin rpy="0 0 0" xyz="0 0 0"/>
  </joint>
  <!-- Attach the sensor arch to the top plate -->
  <joint name="sensor_arch_mount" type="fixed">
    <parent link="sensor_arch_base_link"/>
    <child link="sensor_arch_mount_link"/>
    <origin rpy="0 0 0" xyz="0 0 0.51"/>
  </joint>
  <!--
      IMU Link: Standard location to add an IMU (i.e. UM7 or Microstrain)
  -->
  <link name="husky/base_link/imu_link"/>
  <joint name="imu_joint" type="fixed">
    <origin rpy="0 -1.5708 3.1416" xyz="0.19 0 0.149"/>
    <parent link="base_link"/>
    <child link="husky/base_link/imu_link"/>
  </joint>
  <gazebo reference="husky/base_link/imu_link">
  </gazebo>
   <!-- Spawn the laser sensor  link -->
  <link name="husky/base_link/front_laser">
    <inertial>
      <mass value="1.1"/>
      <origin xyz="0 0 0"/>
      <inertia ixx="0.00307156543804" ixy="0.0" ixz="0.0" iyy="0.0031284904152700005" iyz="0.0" izz="0.00196432421427"/>
    </inertial>
  </link>
 

  <joint name="husky/base_link/front_laser_mount_joint" type="fixed">
    <origin rpy="0 0 0" xyz="-0.023 0.0 0.00"/>
    <parent link="top_plate_front_link"/>
    <child link="husky/base_link/front_laser_mount"/>
  </joint>
  <link name="husky/base_link/front_laser_mount">
    <visual>
      <origin rpy="0 0 0" xyz="0 0 0"/>
      <geometry>
        <!-- Origin of this mesh is the base of the bracket. -->
        <mesh filename="/home/arash/ros2_ws/src/husky_description/meshes/accessories/hokuyo_ust10.stl"/>
      </geometry>
      <material name="dark_grey"/>
    </visual>
    <collision>
      <origin rpy="0 0 0" xyz="0 0 0.0175"/>
      <geometry>
        <box size="0.05 0.05 0.035"/>
      </geometry>
    </collision>
    <collision>
      <origin rpy="0 0 0" xyz="0 0 0.035"/>
      <geometry>
        <cylinder length="0.07" radius="0.024"/>
      </geometry>
    </collision>
  </link>
  <joint name="husky/base_link/front_laser_joint" type="fixed">
    <!-- This offset is from the base of the bracket to the LIDAR's focal point. -->
    <origin rpy="0 0 0" xyz="0 0 0.0474"/>
    <parent link="husky/base_link/front_laser_mount"/>
    <child link="husky/base_link/front_laser"/>
  </joint>
  <gazebo reference="husky/base_link/front_laser_mount">
    <material>Gazebo/DarkGrey</material>
  </gazebo>
  <material name="aluminum">
    <color rgba="0.5 0.5 0.5 1"/>
  </material>
  <material name="plastic">
    <color rgba="0.1 0.1 0.1 1"/>
  </material>
  <!-- camera body, with origin at bottom screw mount -->
  <joint name="camera_realsense_joint" type="fixed">
    <origin rpy="0 0 0" xyz="0 0 0"/>
    <parent link="sensor_arch_mount_link"/>
    <child link="camera_realsense_bottom_screw_frame"/>
  </joint>
  <link name="camera_realsense_bottom_screw_frame"/>
  <joint name="camera_realsense_link_joint" type="fixed">
    <origin rpy="0 0 0" xyz="0.010600000000000002 0.0175 0.0125"/>
    <parent link="camera_realsense_bottom_screw_frame"/>
    <child link="camera_realsense_link"/>
  </joint>
  <link name="camera_realsense_link">
    <visual>
      <!-- the mesh origin is at front plate in between the two infrared camera axes -->
      <origin rpy="1.5707963267948966 0 1.5707963267948966" xyz="0.0043 -0.0175 0"/>
      <geometry>
        <mesh filename="file:///home/arash/ros2_ws/install/realsense2_description/share/realsense2_description/meshes/d435.dae"/>
      </geometry>
    </visual>
    <collision>
      <origin rpy="0 0 0" xyz="0 -0.0175 0"/>
      <geometry>
        <box size="0.02505 0.09 0.025"/>
      </geometry>
    </collision>
    <inertial>
      <!-- The following are not reliable values, and should not be used for modeling -->
      <mass value="0.072"/>
      <origin xyz="0 0 0"/>
      <inertia ixx="0.003881243" ixy="0.0" ixz="0.0" iyy="0.000498940" iyz="0.0" izz="0.003879257"/>
    </inertial>
  </link>
  <!--
       The gazebo plugin aligns the depth data with the Z axis, with X=left and Y=up
       ROS expects the depth data along the X axis, with Y=left and Z=up
       This link only exists to give the gazebo plugin the correctly-oriented frame
     -->
  <link name="camera_realsense_link_gazebo"/>
  <joint name="camera_realsense_link_gazebo_joint" type="fixed">
    <parent link="camera_realsense_link"/>
    <child link="camera_realsense_link_gazebo"/>
    <origin rpy="-1.5707963267948966 0 -1.5707963267948966" xyz="0.0 0 0"/>
  </joint>
 
     


  

<gazebo reference="husky/base_link/imu_link">
  <sensor name="husky/base_link/imu_link" type="imu">
  <always_on>1</always_on>
  <update_rate>100.0</update_rate>
  <visualize>true</visualize>
  <topic>imu</topic>
  <gz_frame_id>husky/base_link/imu_link</gz_frame_id>
  <!-- Noise and Covariance -->
  <imu>
  <angular_velocity>
    <x>
      <noise type="gaussian">
        <mean>0.0</mean>
        <stddev>0.02</stddev>
        <bias_mean>0.0</bias_mean>
        <bias_stddev>0.0005</bias_stddev>
      </noise>
    </x>
    <y>
      <noise type="gaussian">
        <mean>0.0</mean>
        <stddev>0.02</stddev>
        <bias_mean>0.0</bias_mean>
        <bias_stddev>0.0005</bias_stddev>
      </noise>
    </y>
    <z>
      <noise type="gaussian">
        <mean>0.0</mean>
        <stddev>0.02</stddev>
        <bias_mean>0.0</bias_mean>
        <bias_stddev>0.0005</bias_stddev>
      </noise>
    </z>
  </angular_velocity>

  <linear_acceleration>
    <x>
      <noise type="gaussian">
        <mean>0.0</mean>
        <stddev>0.2</stddev>
        <bias_mean>0.0</bias_mean>
        <bias_stddev>0.005</bias_stddev>
      </noise>
    </x>
    <y>
      <noise type="gaussian">
        <mean>0.0</mean>
        <stddev>0.2</stddev>
        <bias_mean>0.0</bias_mean>
        <bias_stddev>0.005</bias_stddev>
      </noise>
    </y>
    <z>
      <noise type="gaussian">
        <mean>0.0</mean>
        <stddev>0.2</stddev>
        <bias_mean>0.0</bias_mean>
        <bias_stddev>0.005</bias_stddev>
      </noise>
    </z>
  </linear_acceleration>
</imu>

</sensor>
</gazebo>
     
 <link name="husky/base_link/gps_link">
    <visual>
    <origin xyz="0 0 0" rpy="0 0 0"/>
    <geometry>
      <cylinder radius="0.02" length="0.04"/>  <!-- Small GPS antenna -->
    </geometry>
    <material name="Black">
      <color rgba="0.1 0.1 0.1 1.0"/>
    </material>
  </visual>
  <collision>
    <origin xyz="0 0 0" rpy="0 0 0"/>
    <geometry>
      <cylinder radius="0.03" length="0.05"/>
    </geometry>
  </collision>
  <inertial>
    <mass value="0.05"/>
    <origin xyz="0 0 0" rpy="0 0 0"/>
    <inertia ixx="1e-6" ixy="0" ixz="0" iyy="1e-6" iyz="0" izz="1e-6"/>
  </inertial>
  </link>
  <joint name="gps_joint" type="fixed">
    <parent link="sensor_arch_mount_link"/>
    <child link="husky/base_link/gps_link"/>
    <origin rpy="-1.5707963267948966 0 -1.5707963267948966" xyz="0.0 0.15 0.01"/>
  </joint>
   <gazebo reference="base_link">
    <sensor name="gps_link" type="navsat">
        <always_on>1</always_on>
        <update_rate>30</update_rate>
        <topic>gps</topic>
          <frame_id>husky/base_link/gps_link</frame_id>
      </sensor> 
  </gazebo>
  <gazebo reference="base_link">
  <sensor name="front_laser" type="gpu_lidar">
    <pose>0.37 0 0.310 0 0 0</pose>
    <update_rate>20</update_rate>
    <ray>
      <scan>
        <horizontal>
          <samples>360</samples>
          <resolution>1</resolution>
          <min_angle>-1.5708</min_angle>
          <max_angle>1.5708</max_angle>
        </horizontal>
      </scan>
      <range>
        <min>0.1</min>
        <max>30</max>
        <resolution>0.01</resolution>
      </range>
    </ray>

    <topic>lidar</topic>
    <frame_id>husky/base_link/front_laser</frame_id>
      <always_on>1</always_on> 
  </sensor>
</gazebo>


<gazebo reference="camera_realsense_link">
  <sensor name="camera_realsense_link" type="rgbd_camera">
    <camera>
      <horizontal_fov>1.3962634</horizontal_fov>
      <image>
        <width>640</width>
        <height>480</height>
        <format>R8G8B8</format>
      </image>
      <clip>
        <near>0.1</near><far>100</far>
      </clip>
       <depth_camera>
            <clip>
              <near>0.1</near>
              <far>10</far>
            </clip>
       </depth_camera>
      <noise>
        <type>gaussian</type><mean>0.0</mean><stddev>0.007</stddev>
      </noise>
     
    </camera>
    <always_on>1</always_on>
    <update_rate>30.0</update_rate>
    
    <gz_frame_id>camera_realsense_link</gz_frame_id>
  </sensor>
</gazebo>

<gazebo>
  <plugin filename="gz-sim-diff-drive-system" name="gz::sim::systems::DiffDrive">
    <left_joint>front_left_wheel</left_joint>
    <left_joint>rear_left_wheel</left_joint>
    <right_joint>front_right_wheel</right_joint>
    <right_joint>rear_right_wheel</right_joint>
    <wheel_separation>0.555</wheel_separation>
    <wheel_radius>0.1651</wheel_radius>
    <max_linear_acceleration>1.0</max_linear_acceleration>
    <topic>cmd_vel</topic>
    <odom_topic>odom</odom_topic>
    <frame_id>odom</frame_id>
    <child_frame_id>base_link</child_frame_id>
    <odom_publisher_frequency>30</odom_publisher_frequency>
    <publish_wheel_tf>true</publish_wheel_tf>
    <publish_odometry_tf>true</publish_odometry_tf>
  </plugin>
</gazebo>
<!--
<gazebo>

<plugin
  filename="gz-sim-odometry-publisher-system"
  name="gz::sim::systems::OdometryPublisher">
  <odom_frame>odom</odom_frame>
  <robot_base_frame>base_link</robot_base_frame>
</plugin>

</gazebo>
-->

  <!-- This file is a placeholder which is included by default from
       husky.urdf.xacro. If a robot is being customized and requires
       additional URDF, set the HUSKY_URDF_EXTRAS environment variable
       to the full path of the file you would like included. -->
  <!-- This file is a placeholder which is included by default from
       husky.urdf.xacro. If a robot is being customized and requires
       additional URDF, set the HUSKY_URDF_EXTRAS environment variable
       to the full path of the file you would like included. -->
</robot>
